Traceback (most recent call last):
  File "/opt/hostedtoolcache/Python/3.9.18/x64/lib/python3.9/site-packages/jupyter_cache/executors/utils.py", line 58, in single_nb_execution
    executenb(
  File "/opt/hostedtoolcache/Python/3.9.18/x64/lib/python3.9/site-packages/nbclient/client.py", line 1305, in execute
    return NotebookClient(nb=nb, resources=resources, km=km, **kwargs).execute()
  File "/opt/hostedtoolcache/Python/3.9.18/x64/lib/python3.9/site-packages/jupyter_core/utils/__init__.py", line 172, in wrapped
    return loop.run_until_complete(inner)
  File "/opt/hostedtoolcache/Python/3.9.18/x64/lib/python3.9/asyncio/base_events.py", line 647, in run_until_complete
    return future.result()
  File "/opt/hostedtoolcache/Python/3.9.18/x64/lib/python3.9/site-packages/nbclient/client.py", line 705, in async_execute
    await self.async_execute_cell(
  File "/opt/hostedtoolcache/Python/3.9.18/x64/lib/python3.9/site-packages/nbclient/client.py", line 1058, in async_execute_cell
    await self._check_raise_for_error(cell, cell_index, exec_reply)
  File "/opt/hostedtoolcache/Python/3.9.18/x64/lib/python3.9/site-packages/nbclient/client.py", line 914, in _check_raise_for_error
    raise CellExecutionError.from_cell_and_msg(cell, exec_reply_content)
nbclient.exceptions.CellExecutionError: An error occurred while executing the following cell:
------------------
test_pi=np.zeros(10)
for i in range(0,10):
    test_pi[i]=montecarlopi(1000);

print('mean value for pi = %f'%np.mean(test_pi))
print('standard deviation is %f'%np.std(test_pi))
print('actual pi is %f'%np.pi)
------------------


[0;31m---------------------------------------------------------------------------[0m
[0;31mTypeError[0m                                 Traceback (most recent call last)
Cell [0;32mIn[6], line 3[0m
[1;32m      1[0m test_pi[38;5;241m=[39mnp[38;5;241m.[39mzeros([38;5;241m10[39m)
[1;32m      2[0m [38;5;28;01mfor[39;00m i [38;5;129;01min[39;00m [38;5;28mrange[39m([38;5;241m0[39m,[38;5;241m10[39m):
[0;32m----> 3[0m     test_pi[i][38;5;241m=[39m[43mmontecarlopi[49m[43m([49m[38;5;241;43m1000[39;49m[43m)[49m;
[1;32m      5[0m [38;5;28mprint[39m([38;5;124m'[39m[38;5;124mmean value for pi = [39m[38;5;132;01m%f[39;00m[38;5;124m'[39m[38;5;241m%[39mnp[38;5;241m.[39mmean(test_pi))
[1;32m      6[0m [38;5;28mprint[39m([38;5;124m'[39m[38;5;124mstandard deviation is [39m[38;5;132;01m%f[39;00m[38;5;124m'[39m[38;5;241m%[39mnp[38;5;241m.[39mstd(test_pi))

Cell [0;32mIn[5], line 15[0m, in [0;36mmontecarlopi[0;34m(N)[0m
[1;32m      1[0m [38;5;28;01mdef[39;00m [38;5;21mmontecarlopi[39m(N):
[1;32m      2[0m [38;5;250m    [39m[38;5;124;03m'''Create random x-y-coordinates to and use ratio of circle-to-square to [39;00m
[1;32m      3[0m [38;5;124;03m    calculate the value of pi[39;00m
[1;32m      4[0m [38;5;124;03m    i.e. Acircle/Asquare = pi/4[39;00m
[0;32m   (...)[0m
[1;32m     11[0m [38;5;124;03m    our_pi: the best prediction of pi using N points[39;00m
[1;32m     12[0m [38;5;124;03m    '''[39;00m
[0;32m---> 15[0m     x [38;5;241m=[39m [43mrng[49m[38;5;241;43m.[39;49m[43mrandom[49m[43m([49m[43mN[49m[43m,[49m[38;5;241;43m1[39;49m[43m)[49m;
[1;32m     16[0m     y [38;5;241m=[39m rng[38;5;241m.[39mrandom(N,[38;5;241m1[39m);
[1;32m     17[0m     R[38;5;241m=[39mnp[38;5;241m.[39msqrt(x[38;5;241m*[39m[38;5;241m*[39m[38;5;241m2[39m[38;5;241m+[39my[38;5;241m*[39m[38;5;241m*[39m[38;5;241m2[39m); [38;5;66;03m# compute radius[39;00m

File [0;32mnumpy/random/_generator.pyx:354[0m, in [0;36mnumpy.random._generator.Generator.random[0;34m()[0m

[0;31mTypeError[0m: Cannot interpret '1' as a data type

