Traceback (most recent call last):
  File "/opt/hostedtoolcache/Python/3.9.18/x64/lib/python3.9/site-packages/jupyter_cache/executors/utils.py", line 58, in single_nb_execution
    executenb(
  File "/opt/hostedtoolcache/Python/3.9.18/x64/lib/python3.9/site-packages/nbclient/client.py", line 1305, in execute
    return NotebookClient(nb=nb, resources=resources, km=km, **kwargs).execute()
  File "/opt/hostedtoolcache/Python/3.9.18/x64/lib/python3.9/site-packages/jupyter_core/utils/__init__.py", line 172, in wrapped
    return loop.run_until_complete(inner)
  File "/opt/hostedtoolcache/Python/3.9.18/x64/lib/python3.9/asyncio/base_events.py", line 647, in run_until_complete
    return future.result()
  File "/opt/hostedtoolcache/Python/3.9.18/x64/lib/python3.9/site-packages/nbclient/client.py", line 705, in async_execute
    await self.async_execute_cell(
  File "/opt/hostedtoolcache/Python/3.9.18/x64/lib/python3.9/site-packages/nbclient/client.py", line 1058, in async_execute_cell
    await self._check_raise_for_error(cell, cell_index, exec_reply)
  File "/opt/hostedtoolcache/Python/3.9.18/x64/lib/python3.9/site-packages/nbclient/client.py", line 914, in _check_raise_for_error
    raise CellExecutionError.from_cell_and_msg(cell, exec_reply_content)
nbclient.exceptions.CellExecutionError: An error occurred while executing the following cell:
------------------
from __future__ import print_function
from ipywidgets import interact, interactive, fixed, interact_manual
import ipywidgets as widgets

def f(s):
    plt.plot(r[ix],r[iy],'-',color=(0,0,0,1))
    plt.plot(r[ix]+u[ix]*s,r[iy]+u[iy]*s,'-',color=(1,0,0,1))
    #plt.quiver(r[ix],r[iy],u[ix],u[iy],color=(0,0,1,1),label='displacements')
    plt.quiver(r[ix],r[iy],F[ix],F[iy],color=(1,0,0,1),label='applied forces')
    plt.quiver(r[ix],r[iy],u[ix],u[iy],color=(0,0,1,1),label='displacements')
    plt.axis(l*np.array([-0.5,3.5,-0.5,2]))
    plt.xlabel('x (mm)')
    plt.ylabel('y (mm)')
    plt.title('Deformation scale = {:.1f}x'.format(s))
    plt.legend(bbox_to_anchor=(1,0.5))
interact(f,s=(0,10,1));
------------------


[0;31m---------------------------------------------------------------------------[0m
[0;31mModuleNotFoundError[0m                       Traceback (most recent call last)
Cell [0;32mIn[19], line 2[0m
[1;32m      1[0m [38;5;28;01mfrom[39;00m [38;5;21;01m__future__[39;00m [38;5;28;01mimport[39;00m print_function
[0;32m----> 2[0m [38;5;28;01mfrom[39;00m [38;5;21;01mipywidgets[39;00m [38;5;28;01mimport[39;00m interact, interactive, fixed, interact_manual
[1;32m      3[0m [38;5;28;01mimport[39;00m [38;5;21;01mipywidgets[39;00m [38;5;28;01mas[39;00m [38;5;21;01mwidgets[39;00m
[1;32m      5[0m [38;5;28;01mdef[39;00m [38;5;21mf[39m(s):

[0;31mModuleNotFoundError[0m: No module named 'ipywidgets'

